2023-07-28 14:31:43,036 INFO    StreamThr :26232 [internal.py:wandb_internal():86] W&B internal server running at pid: 26232, started at: 2023-07-28 14:31:43.035779
2023-07-28 14:31:43,038 DEBUG   HandlerThread:26232 [handler.py:handle_request():144] handle_request: status
2023-07-28 14:31:43,057 INFO    WriterThread:26232 [datastore.py:open_for_write():85] open: D:\workspace\Ml-ops\outputs\2023-07-28\14-31-27\wandb\run-20230728_143143-nlybd12c\run-nlybd12c.wandb
2023-07-28 14:31:43,058 DEBUG   SenderThread:26232 [sender.py:send():379] send: header
2023-07-28 14:31:43,062 DEBUG   SenderThread:26232 [sender.py:send():379] send: run
2023-07-28 14:31:43,064 INFO    SenderThread:26232 [sender.py:_maybe_setup_resume():758] checking resume status for raviraja/MLOps Basics/nlybd12c
2023-07-28 14:31:44,553 ERROR   SenderThread:26232 [internal_api.py:execute():325] 404 response executing GraphQL.
2023-07-28 14:31:44,553 ERROR   SenderThread:26232 [internal_api.py:execute():326] {"errors":[{"message":"project not found","path":["upsertBucket"]}],"data":{"upsertBucket":null}}
2023-07-28 14:31:44,566 ERROR   SenderThread:26232 [sender.py:send_run():976] It appears that you do not have permission to access the requested resource. Please reach out to the project owner to grant you access. If you have the correct permissions, verify that there are no issues with your networking setup.(Error 404: Not Found)
Traceback (most recent call last):
  File "D:\workspace\Ml-ops\.venv\lib\site-packages\wandb\sdk\lib\retry.py", line 131, in __call__
    result = self._call_fn(*args, **kwargs)
  File "D:\workspace\Ml-ops\.venv\lib\site-packages\wandb\sdk\internal\internal_api.py", line 322, in execute
    return self.client.execute(*args, **kwargs)  # type: ignore
  File "D:\workspace\Ml-ops\.venv\lib\site-packages\wandb\vendor\gql-0.2.0\wandb_gql\client.py", line 52, in execute
    result = self._get_result(document, *args, **kwargs)
  File "D:\workspace\Ml-ops\.venv\lib\site-packages\wandb\vendor\gql-0.2.0\wandb_gql\client.py", line 60, in _get_result
    return self.transport.execute(document, *args, **kwargs)
  File "D:\workspace\Ml-ops\.venv\lib\site-packages\wandb\sdk\lib\gql_request.py", line 56, in execute
    request.raise_for_status()
  File "D:\workspace\Ml-ops\.venv\lib\site-packages\requests\models.py", line 1021, in raise_for_status
    raise HTTPError(http_error_msg, response=self)
requests.exceptions.HTTPError: 404 Client Error: Not Found for url: https://api.wandb.ai/graphql

During handling of the above exception, another exception occurred:

Traceback (most recent call last):
  File "D:\workspace\Ml-ops\.venv\lib\site-packages\wandb\sdk\internal\sender.py", line 974, in send_run
    self._init_run(run, config_value_dict)
  File "D:\workspace\Ml-ops\.venv\lib\site-packages\wandb\sdk\internal\sender.py", line 1012, in _init_run
    server_run, inserted, server_messages = self._api.upsert_run(
  File "D:\workspace\Ml-ops\.venv\lib\site-packages\wandb\apis\normalize.py", line 73, in wrapper
    raise err
  File "D:\workspace\Ml-ops\.venv\lib\site-packages\wandb\apis\normalize.py", line 41, in wrapper
    return func(*args, **kwargs)
  File "D:\workspace\Ml-ops\.venv\lib\site-packages\wandb\sdk\internal\internal_api.py", line 1825, in upsert_run
    response = self.gql(
  File "D:\workspace\Ml-ops\.venv\lib\site-packages\wandb\sdk\internal\internal_api.py", line 294, in gql
    ret = self._retry_gql(
  File "D:\workspace\Ml-ops\.venv\lib\site-packages\wandb\sdk\lib\retry.py", line 147, in __call__
    retry_timedelta_triggered = check_retry_fn(e)
  File "D:\workspace\Ml-ops\.venv\lib\site-packages\wandb\util.py", line 946, in check_retry_fn
    return fallback_retry_fn(e)
  File "D:\workspace\Ml-ops\.venv\lib\site-packages\wandb\util.py", line 888, in no_retry_auth
    raise CommError(
wandb.errors.CommError: It appears that you do not have permission to access the requested resource. Please reach out to the project owner to grant you access. If you have the correct permissions, verify that there are no issues with your networking setup.(Error 404: Not Found)
2023-07-28 14:31:45,901 DEBUG   HandlerThread:26232 [handler.py:handle_request():144] handle_request: shutdown
2023-07-28 14:31:45,901 INFO    HandlerThread:26232 [handler.py:finish():857] shutting down handler
2023-07-28 14:31:46,090 INFO    WriterThread:26232 [datastore.py:close():294] close: D:\workspace\Ml-ops\outputs\2023-07-28\14-31-27\wandb\run-20230728_143143-nlybd12c\run-nlybd12c.wandb
2023-07-28 14:31:46,606 INFO    SenderThread:26232 [sender.py:finish():1552] shutting down sender
